Workbook

Sheet Qatar 2022
A1: POSICIÓN | C1: TOTALES
D2: 44885 | G2: 44886 | J2: 44886 | M2: 44886 | P2: 44887 | S2: 44887 | V2: 44887 | Y2: 44887 | AB2: 44888 | AE2: 44888 | AH2: 44888 | AK2: 44888 | AN2: 44889 | AQ2: 44889 | AT2: 44889 | AW2: 44889 | AZ2: 44890 | BC2: 44890 | BF2: 44890 | BI2: 44890 | BL2: 44891 | BO2: 44891 | BR2: 44891 | BU2: 44891 | BX2: 44892 | CA2: 44892 | CD2: 44892 | CG2: 44892 | CJ2: 44893 | CM2: 44893 | CP2: 44893 | CS2: 44893 | CV2: 44894 | CY2: 44894 | DB2: 44894 | DE2: 44894 | DH2: 44895 | DK2: 44895 | DN2: 44895 | DQ2: 44895 | DT2: 44896 | DW2: 44896 | DZ2: 44896 | EC2: 44896 | EF2: 44897 | EI2: 44897 | EL2: 44897 | EO2: 44897
D3: 0.5 | G3: 0.5 | J3: 0.375 | M3: 0.625 | P3: 0.25 | S3: 0.5 | V3: 0.375 | Y3: 0.625 | AB3: 0.375 | AE3: 0.5 | AH3: 0.25 | AK3: 0.625 | AN3: 0.25 | AQ3: 0.625 | AT3: 0.375 | AW3: 0.5 | AZ3: 0.375 | BC3: 0.5 | BF3: 0.25 | BI3: 0.625 | BL3: 0.375 | BO3: 0.625 | BR3: 0.25 | BU3: 0.5 | BX3: 0.25 | CA3: 0.625 | CD3: 0.375 | CG3: 0.5 | CJ3: 0.25 | CM3: 0.5 | CP3: 0.375 | CS3: 0.625 | CV3: 0.45833333 | CY3: 0.45833333 | DB3: 0.625 | DE3: 0.625 | DH3: 0.625 | DK3: 0.625 | DN3: 0.45833333 | DQ3: 0.45833333 | DT3: 0.625 | DW3: 0.625 | DZ3: 0.45833333 | EC3: 0.45833333 | EF3: 0.625 | EI3: 0.625 | EL3: 0.45833333 | EO3: 0.45833333
D5: =Clasificados!C4 -> QATAR | E5: =Clasificados!C5 -> ECUADOR | F5: PUNTOS | G5: =Clasificados!C6 -> SENEGAL | H5: =Clasificados!C7 -> PAISES BAJOS | I5: PUNTOS | J5: =Clasificados!H4 -> INGLATERRA | K5: =Clasificados!H5 -> IRÁN | L5: PUNTOS | M5: =Clasificados!H6 -> ESTADOS UNIDOS | N5: =Clasificados!H7 -> GALES | O5: PUNTOS | P5: =Clasificados!C10 -> ARGENTINA | Q5: =Clasificados!C11 -> ARABIA SAUDITA | R5: PUNTOS | S5: =Clasificados!C12 -> MÉXICO | T5: =Clasificados!C13 -> POLONIA | U5: PUNTOS | V5: =Clasificados!H10 -> DINAMARCA | W5: =Clasificados!H11 -> TÚNEZ | X5: PUNTOS | Y5: =Clasificados!H12 -> FRANCIA | Z5: =Clasificados!H13 -> AUSTRALIA | AA5: PUNTOS | AB5: =Clasificados!C16 -> ALEMANIA | AC5: =Clasificados!C17 -> JAPÓN | AD5: PUNTOS | AE5: =Clasificados!C18 -> ESPAÑA | AF5: =Clasificados!C19 -> COSTA RICA | AG5: PUNTOS | AH5: =Clasificados!H16 -> MARRUECOS | AI5: =Clasificados!H17 -> CROACIA | AJ5: PUNTOS | AK5: =Clasificados!H18 -> BÉLGICA | AL5: =Clasificados!H19 -> CANADÁ | AM5: PUNTOS | AN5: =Clasificados!C22 -> SUIZA | AO5: =Clasificados!C23 -> CAMERÚN | AP5: PUNTOS | AQ5: =Clasificados!C24 -> BRASIL | AR5: =Clasificados!C25 -> SERBIA | AS5: PUNTOS | AT5: =Clasificados!H22 -> URUGUAY | AU5: =Clasificados!H23 -> COREA DEL SUR | AV5: PUNTOS | AW5: =Clasificados!H24 -> PORTUGAL | AX5: =Clasificados!H25 -> GHANA | AY5: PUNTOS | AZ5: =D5 -> QATAR | BA5: =G5 -> SENEGAL | BB5: PUNTOS | BC5: =H5 -> PAISES BAJOS | BD5: =E5 -> ECUADOR | BE5: PUNTOS | BF5: =N5 -> GALES | BG5: =K5 -> IRÁN | BH5: PUNTOS | BI5: =J5 -> INGLATERRA | BJ5: =M5 -> ESTADOS UNIDOS | BK5: PUNTOS | BL5: =T5 -> POLONIA | BM5: =Q5 -> ARABIA SAUDITA | BN5: PUNTOS | BO5: =P5 -> ARGENTINA | BP5: =S5 -> MÉXICO | BQ5: PUNTOS | BR5: =W5 -> TÚNEZ | BS5: =Z5 -> AUSTRALIA | BT5: PUNTOS | BU5: =Y5 -> FRANCIA | BV5: =V5 -> DINAMARCA | BW5: PUNTOS | BX5: =AC5 -> JAPÓN | BY5: =AF5 -> COSTA RICA | BZ5: PUNTOS | CA5: =AE5 -> ESPAÑA | CB5: =AB5 -> ALEMANIA | CC5: PUNTOS | CD5: =AK5 -> BÉLGICA | CE5: =AH5 -> MARRUECOS | CF5: PUNTOS | CG5: =AI5 -> CROACIA | CH5: =AL5 -> CANADÁ | CI5: PUNTOS | CJ5: =AO5 -> CAMERÚN | CK5: =AR5 -> SERBIA | CL5: PUNTOS | CM5: =AQ5 -> BRASIL | CN5: =AN5 -> SUIZA | CO5: PUNTOS | CP5: =AU5 -> COREA DEL SUR | CQ5: =AX5 -> GHANA | CR5: PUNTOS | CS5: =AW5 -> PORTUGAL | CT5: =AT5 -> URUGUAY | CU5: PUNTOS | CV5: =E5 -> ECUADOR | CW5: =G5 -> SENEGAL | CX5: PUNTOS | CY5: =H5 -> PAISES BAJOS | CZ5: =D5 -> QATAR | DA5: PUNTOS | DB5: =N5 -> GALES | DC5: =J5 -> INGLATERRA | DD5: PUNTOS | DE5: =K5 -> IRÁN | DF5: =M5 -> ESTADOS UNIDOS | DG5: PUNTOS | DH5: =Q5 -> ARABIA SAUDITA | DI5: =S5 -> MÉXICO | DJ5: PUNTOS | DK5: =T5 -> POLONIA | DL5: =P5 -> ARGENTINA | DM5: PUNTOS | DN5: =W5 -> TÚNEZ | DO5: =Y5 -> FRANCIA | DP5: PUNTOS | DQ5: =Z5 -> AUSTRALIA | DR5: =V5 -> DINAMARCA | DS5: PUNTOS | DT5: =AC5 -> JAPÓN | DU5: =AE5 -> ESPAÑA | DV5: PUNTOS | DW5: =AF5 -> COSTA RICA | DX5: =AB5 -> ALEMANIA | DY5: PUNTOS | DZ5: =AI5 -> CROACIA | EA5: =AK5 -> BÉLGICA | EB5: PUNTOS | EC5: =AL5 -> CANADÁ | ED5: =AH5 -> MARRUECOS | EE5: PUNTOS | EF5: =AR5 -> SERBIA | EG5: =AN5 -> SUIZA | EH5: PUNTOS | EI5: =AO5 -> CAMERÚN | EJ5: =AQ5 -> BRASIL | EK5: PUNTOS | EL5: =AU5 -> COREA DEL SUR | EM5: =AW5 -> PORTUGAL | EN5: PUNTOS | EO5: =AX5 -> GHANA | EP5: =AT5 -> URUGUAY | EQ5: PUNTOS | ER5: TOTAL
D6: GRUPO A | J6: GRUPO B | P6: GRUPO C | V6: GRUPO D | AB6: GRUPO E | AH6: GRUPO F | AN6: GRUPO G | AT6: GRUPO H | AZ6: GRUPO A | BF6: GRUPO B | BL6: GRUPO C | BR6: GRUPO D | BX6: GRUPO E | CD6: GRUPO F | CJ6: GRUPO G | CP6: GRUPO H | CV6: GRUPO A | DB6: GRUPO B | DH6: GRUPO C | DN6: GRUPO D | DT6: GRUPO E | DZ6: GRUPO F | EF6: GRUPO G | EL6: GRUPO H
C7: =ER7 -> 21 | D7: =IF(AND(D8="",E8=""),"No Jugado",IF(D8>E8,D5,(IF(D8=E8,"Empate",E5)))) -> ECUADOR | F7: =IF(AND(D$8="",E$8=""),0,IF(AND(D$8=D7,E$8=E7),5,IF(AND(D$8=E$8,D7=E7),3,IF(AND(D$8>E$8,D7>E7),3,IF(AND(D$8<E$8,D7<E7),3,0))))) -> 0 | G7: =IF(AND(G8="",H8=""),"No Jugado",IF(G8>H8,G5,(IF(G8=H8,"Empate",H5)))) -> PAISES BAJOS | I7: =IF(AND(G$8="",H$8=""),0,IF(AND(G$8=G7,H$8=H7),5,IF(AND(G$8=H$8,G7=H7),3,IF(AND(G$8>H$8,G7>H7),3,IF(AND(G$8<H$8,G7<H7),3,0))))) -> 0 | J7: =IF(AND(J8="",K8=""),"No Jugado",IF(J8>K8,J5,(IF(J8=K8,"Empate",K5)))) -> INGLATERRA | L7: =IF(AND(J$8="",K$8=""),0,IF(AND(J$8=J7,K$8=K7),5,IF(AND(J$8=K$8,J7=K7),3,IF(AND(J$8>K$8,J7>K7),3,IF(AND(J$8<K$8,J7<K7),3,0))))) -> 3 | M7: =IF(AND(M8="",N8=""),"No Jugado",IF(M8>N8,M5,(IF(M8=N8,"Empate",N5)))) -> Empate | O7: =IF(AND(M$8="",N$8=""),0,IF(AND(M$8=M7,N$8=N7),5,IF(AND(M$8=N$8,M7=N7),3,IF(AND(M$8>N$8,M7>N7),3,IF(AND(M$8<N$8,M7<N7),3,0))))) -> 0 | P7: =IF(AND(P8="",Q8=""),"No Jugado",IF(P8>Q8,P5,(IF(P8=Q8,"Empate",Q5)))) -> ARABIA SAUDITA | R7: =IF(AND(P$8="",Q$8=""),0,IF(AND(P$8=P7,Q$8=Q7),5,IF(AND(P$8=Q$8,P7=Q7),3,IF(AND(P$8>Q$8,P7>Q7),3,IF(AND(P$8<Q$8,P7<Q7),3,0))))) -> 0 | S7: =IF(AND(S8="",S8=""),"No Jugado",IF(S8>T8,S5,(IF(S8=T8,"Empate",T5)))) -> Empate | U7: =IF(AND(S$8="",T$8=""),0,IF(AND(S$8=S7,T$8=T7),5,IF(AND(S$8=T$8,S7=T7),3,IF(AND(S$8>T$8,S7>T7),3,IF(AND(S$8<T$8,S7<T7),3,0))))) -> 0 | V7: =IF(AND(V8="",W8=""),"No Jugado",IF(V8>W8,V5,(IF(V8=W8,"Empate",W5)))) -> Empate | X7: =IF(AND(V$8="",W$8=""),0,IF(AND(V$8=V7,W$8=W7),5,IF(AND(V$8=W$8,V7=W7),3,IF(AND(V$8>W$8,V7>W7),3,IF(AND(V$8<W$8,V7<W7),3,0))))) -> 0 | Y7: =IF(AND(Y8="",Z8=""),"No Jugado",IF(Y8>Z8,Y5,(IF(Y8=Z8,"Empate",Z5)))) -> FRANCIA | AA7: =IF(AND(Y$8="",Z$8=""),0,IF(AND(Y$8=Y7,Z$8=Z7),5,IF(AND(Y$8=Z$8,Y7=Z7),3,IF(AND(Y$8>Z$8,Y7>Z7),3,IF(AND(Y$8<Z$8,Y7<Z7),3,0))))) -> 3 | AB7: =IF(AND(AB8="",AC8=""),"No Jugado",IF(AB8>AC8,AB5,(IF(AB8=AC8,"Empate",AC5)))) -> JAPÓN | AD7: =IF(AND(AB$8="",AC$8=""),0,IF(AND(AB$8=AB7,AC$8=AC7),5,IF(AND(AB$8=AC$8,AB7=AC7),3,IF(AND(AB$8>AC$8,AB7>AC7),3,IF(AND(AB$8<AC$8,AB7<AC7),3,0))))) -> 0 | AE7: =IF(AND(AE8="",AF8=""),"No Jugado",IF(AE8>AF8,AE5,(IF(AE8=AF8,"Empate",AF5)))) -> ESPAÑA | AG7: =IF(AND(AE$8="",AF$8=""),0,IF(AND(AE$8=AE7,AF$8=AF7),5,IF(AND(AE$8=AF$8,AE7=AF7),3,IF(AND(AE$8>AF$8,AE7>AF7),3,IF(AND(AE$8<AF$8,AE7<AF7),3,0))))) -> 3 | AH7: =IF(AND(AH8="",AI8=""),"No Jugado",IF(AH8>AI8,AH5,(IF(AH8=AI8,"Empate",AI5)))) -> Empate | AJ7: =IF(AND(AH$8="",AI$8=""),0,IF(AND(AH$8=AH7,AI$8=AI7),5,IF(AND(AH$8=AI$8,AH7=AI7),3,IF(AND(AH$8>AI$8,AH7>AI7),3,IF(AND(AH$8<AI$8,AH7<AI7),3,0))))) -> 0 | AK7: =IF(AND(AK8="",AL8=""),"No Jugado",IF(AK8>AL8,AK5,(IF(AK8=AL8,"Empate",AL5)))) -> BÉLGICA | AM7: =IF(AND(AK$8="",AL$8=""),0,IF(AND(AK$8=AK7,AL$8=AL7),5,IF(AND(AK$8=AL$8,AK7=AL7),3,IF(AND(AK$8>AL$8,AK7>AL7),3,IF(AND(AK$8<AL$8,AK7<AL7),3,0))))) -> 3 | AN7: =IF(AND(AN8="",AO8=""),"No Jugado",IF(AN8>AO8,AN5,(IF(AN8=AO8,"Empate",AO5)))) -> SUIZA | AP7: =IF(AND(AN$8="",AO$8=""),0,IF(AND(AN$8=AN7,AO$8=AO7),5,IF(AND(AN$8=AO$8,AN7=AO7),3,IF(AND(AN$8>AO$8,AN7>AO7),3,IF(AND(AN$8<AO$8,AN7<AO7),3,0))))) -> 3 | AQ7: =IF(AND(AQ8="",AR8=""),"No Jugado",IF(AQ8>AR8,AQ5,(IF(AQ8=AR8,"Empate",AR5)))) -> BRASIL | AS7: =IF(AND(AQ$8="",AR$8=""),0,IF(AND(AQ$8=AQ7,AR$8=AR7),5,IF(AND(AQ$8=AR$8,AQ7=AR7),3,IF(AND(AQ$8>AR$8,AQ7>AR7),3,IF(AND(AQ$8<AR$8,AQ7<AR7),3,0))))) -> 3 | AT7: =IF(AND(AT8="",AU8=""),"No Jugado",IF(AT8>AU8,AT5,(IF(AT8=AU8,"Empate",AU5)))) -> Empate | AV7: =IF(AND(AT$8="",AU$8=""),0,IF(AND(AT$8=AT7,AU$8=AU7),5,IF(AND(AT$8=AU$8,AT7=AU7),3,IF(AND(AT$8>AU$8,AT7>AU7),3,IF(AND(AT$8<AU$8,AT7<AU7),3,0))))) -> 0 | AW7: =IF(AND(AW8="",AX8=""),"No Jugado",IF(AW8>AX8,AW5,(IF(AW8=AX8,"Empate",AX5)))) -> PORTUGAL | AY7: =IF(AND(AW$8="",AX$8=""),0,IF(AND(AW$8=AW7,AX$8=AX7),5,IF(AND(AW$8=AX$8,AW7=AX7),3,IF(AND(AW$8>AX$8,AW7>AX7),3,IF(AND(AW$8<AX$8,AW7<AX7),3,0))))) -> 3 | AZ7: =IF(AND(AZ8="",BA8=""),"No Jugado",IF(AZ8>BA8,AZ5,(IF(AZ8=BA8,"Empate",BA5)))) -> SENEGAL | BB7: =IF(AND(AZ$8="",BA$8=""),0,IF(AND(AZ$8=AZ7,BA$8=BA7),5,IF(AND(AZ$8=BA$8,AZ7=BA7),3,IF(AND(AZ$8>BA$8,AZ7>BA7),3,IF(AND(AZ$8<BA$8,AZ7<BA7),3,0))))) -> 0 | BC7: =IF(AND(BC8="",BD8=""),"No Jugado",IF(BC8>BD8,BC5,(IF(BC8=BD8,"Empate",BD5)))) -> No Jugado | BE7: =IF(AND(BC$8="",BD$8=""),0,IF(AND(BC$8=BC7,BD$8=BD7),5,IF(AND(BC$8=BD$8,BC7=BD7),3,IF(AND(BC$8>BD$8,BC7>BD7),3,IF(AND(BC$8<BD$8,BC7<BD7),3,0))))) -> 0 | BF7: =IF(AND(BF8="",BG8=""),"No Jugado",IF(BF8>BG8,BF5,(IF(BF8=BG8,"Empate",BG5)))) -> IRÁN | BH7: =IF(AND(BF$8="",BG$8=""),0,IF(AND(BF$8=BF7,BG$8=BG7),5,IF(AND(BF$8=BG$8,BF7=BG7),3,IF(AND(BF$8>BG$8,BF7>BG7),3,IF(AND(BF$8<BG$8,BF7<BG7),3,0))))) -> 0 | BI7: =IF(AND(BI8="",BJ8=""),"No Jugado",IF(BI8>BJ8,BI5,(IF(BI8=BJ8,"Empate",BJ5)))) -> No Jugado | BK7: =IF(AND(BI$8="",BJ$8=""),0,IF(AND(BI$8=BI7,BJ$8=BJ7),5,IF(AND(BI$8=BJ$8,BI7=BJ7),3,IF(AND(BI$8>BJ$8,BI7>BJ7),3,IF(AND(BI$8<BJ$8,BI7<BJ7),3,0))))) -> 0 | BL7: =IF(AND(BL8="",BM8=""),"No Jugado",IF(BL8>BM8,BL5,(IF(BL8=BM8,"Empate",BM5)))) -> No Jugado | BN7: =IF(AND(BL$8="",BM$8=""),0,IF(AND(BL$8=BL7,BM$8=BM7),5,IF(AND(BL$8=BM$8,BL7=BM7),3,IF(AND(BL$8>BM$8,BL7>BM7),3,IF(AND(BL$8<BM$8,BL7<BM7),3,0))))) -> 0 | BO7: =IF(AND(BO8="",BP8=""),"No Jugado",IF(BO8>BP8,BO5,(IF(BO8=BP8,"Empate",BP5)))) -> No Jugado | BQ7: =IF(AND(BO$8="",BP$8=""),0,IF(AND(BO$8=BO7,BP$8=BP7),5,IF(AND(BO$8=BP$8,BO7=BP7),3,IF(AND(BO$8>BP$8,BO7>BP7),3,IF(AND(BO$8<BP$8,BO7<BP7),3,0))))) -> 0 | BR7: =IF(AND(BR8="",BS8=""),"No Jugado",IF(BR8>BS8,BR5,(IF(BR8=BS8,"Empate",BS5)))) -> No Jugado | BU7: =IF(AND(BU8="",BV8=""),"No Jugado",IF(BU8>BV8,BU5,(IF(BU8=BV8,"Empate",BV5)))) -> No Jugado | BW7: =IF(AND(BU$8="",BV$8=""),0,IF(AND(BU$8=BU7,BV$8=BV7),5,IF(AND(BU$8=BV$8,BU7=BV7),3,IF(AND(BU$8>BV$8,BU7>BV7),3,IF(AND(BU$8<BV$8,BU7<BV7),3,0))))) -> 0 | BX7: =IF(AND(BX8="",BY8=""),"No Jugado",IF(BX8>BY8,BX5,(IF(BX8=BY8,"Empate",BY5)))) -> No Jugado | BZ7: =IF(AND(BX$8="",BY$8=""),0,IF(AND(BX$8=BX7,BY$8=BY7),5,IF(AND(BX$8=BY$8,BX7=BY7),3,IF(AND(BX$8>BY$8,BX7>BY7),3,IF(AND(BX$8<BY$8,BX7<BY7),3,0))))) -> 0 | CA7: =IF(AND(CA8="",CB8=""),"No Jugado",IF(CA8>CB8,CA5,(IF(CA8=CB8,"Empate",CB5)))) -> No Jugado | CC7: =IF(AND(CA$8="",CB$8=""),0,IF(AND(CA$8=CA7,CB$8=CB7),5,IF(AND(CA$8=CB$8,CA7=CB7),3,IF(AND(CA$8>CB$8,CA7>CB7),3,IF(AND(CA$8<CB$8,CA7<CB7),3,0))))) -> 0 | CD7: =IF(AND(CD8="",CE8=""),"No Jugado",IF(CD8>CE8,CD5,(IF(CD8=CE8,"Empate",CE5)))) -> No Jugado | CF7: =IF(AND(CD$8="",CE$8=""),0,IF(AND(CD$8=CD7,CE$8=CE7),5,IF(AND(CD$8=CE$8,CD7=CE7),3,IF(AND(CD$8>CE$8,CD7>CE7),3,IF(AND(CD$8<CE$8,CD7<CE7),3,0))))) -> 0 | CG7: =IF(AND(CG8="",CH8=""),"No Jugado",IF(CG8>CH8,CG5,(IF(CG8=CH8,"Empate",CH5)))) -> No Jugado | CI7: =IF(AND(CG$8="",CH$8=""),0,IF(AND(CG$8=CG7,CH$8=CH7),5,IF(AND(CG$8=CH$8,CG7=CH7),3,IF(AND(CG$8>CH$8,CG7>CH7),3,IF(AND(CG$8<CH$8,CG7<CH7),3,0))))) -> 0 | CJ7: =IF(AND(CJ8="",CK8=""),"No Jugado",IF(CJ8>CK8,CJ5,(IF(CJ8=CK8,"Empate",CK5)))) -> No Jugado | CL7: =IF(AND(CJ$8="",CK$8=""),0,IF(AND(CJ$8=CJ7,CK$8=CK7),5,IF(AND(CJ$8=CK$8,CJ7=CK7),3,IF(AND(CJ$8>CK$8,CJ7>CK7),3,IF(AND(CJ$8<CK$8,CJ7<CK7),3,0))))) -> 0 | CM7: =IF(AND(CM8="",CN8=""),"No Jugado",IF(CM8>CN8,CM5,(IF(CM8=CN8,"Empate",CN5)))) -> No Jugado | CO7: =IF(AND(CM$8="",CN$8=""),0,IF(AND(CM$8=CM7,CN$8=CN7),5,IF(AND(CM$8=CN$8,CM7=CN7),3,IF(AND(CM$8>CN$8,CM7>CN7),3,IF(AND(CM$8<CN$8,CM7<CN7),3,0))))) -> 0 | CP7: =IF(AND(CP8="",CQ8=""),"No Jugado",IF(CP8>CQ8,CP5,(IF(CP8=CQ8,"Empate",CQ5)))) -> No Jugado | CR7: =IF(AND(CP$8="",CQ$8=""),0,IF(AND(CP$8=CP7,CQ$8=CQ7),5,IF(AND(CP$8=CQ$8,CP7=CQ7),3,IF(AND(CP$8>CQ$8,CP7>CQ7),3,IF(AND(CP$8<CQ$8,CP7<CQ7),3,0))))) -> 0 | CS7: =IF(AND(CS8="",CT8=""),"No Jugado",IF(CS8>CT8,CS5,(IF(CS8=CT8,"Empate",CT5)))) -> No Jugado | CU7: =IF(AND(CS$8="",CT$8=""),0,IF(AND(CS$8=CS7,CT$8=CT7),5,IF(AND(CS$8=CT$8,CS7=CT7),3,IF(AND(CS$8>CT$8,CS7>CT7),3,IF(AND(CS$8<CT$8,CS7<CT7),3,0))))) -> 0 | CV7: =IF(AND(CV8="",CW8=""),"No Jugado",IF(CV8>CW8,CV5,(IF(CV8=CW8,"Empate",CW5)))) -> No Jugado | CX7: =IF(AND(CV$8="",CW$8=""),0,IF(AND(CV$8=CV7,CW$8=CW7),5,IF(AND(CV$8=CW$8,CV7=CW7),3,IF(AND(CV$8>CW$8,CV7>CW7),3,IF(AND(CV$8<CW$8,CV7<CW7),3,0))))) -> 0 | CY7: =IF(AND(CY8="",CZ8=""),"No Jugado",IF(CY8>CZ8,CY5,(IF(CY8=CZ8,"Empate",CZ5)))) -> No Jugado | DA7: =IF(AND(CY$8="",CZ$8=""),0,IF(AND(CY$8=CY7,CZ$8=CZ7),5,IF(AND(CY$8=CZ$8,CY7=CZ7),3,IF(AND(CY$8>CZ$8,CY7>CZ7),3,IF(AND(CY$8<CZ$8,CY7<CZ7),3,0))))) -> 0 | DB7: =IF(AND(DB8="",DC8=""),"No Jugado",IF(DB8>DC8,DB5,(IF(DB8=DC8,"Empate",DC5)))) -> No Jugado | DD7: =IF(AND(DB$8="",DC$8=""),0,IF(AND(DB$8=DB7,DC$8=DC7),5,IF(AND(DB$8=DC$8,DB7=DC7),3,IF(AND(DB$8>DC$8,DB7>DC7),3,IF(AND(DB$8<DC$8,DB7<DC7),3,0))))) -> 0 | DE7: =IF(AND(DE8="",DF8=""),"No Jugado",IF(DE8>DF8,DE5,(IF(DE8=DF8,"Empate",DF5)))) -> No Jugado | DG7: =IF(AND(DE$8="",DF$8=""),0,IF(AND(DE$8=DE7,DF$8=DF7),5,IF(AND(DE$8=DF$8,DE7=DF7),3,IF(AND(DE$8>DF$8,DE7>DF7),3,IF(AND(DE$8<DF$8,DE7<DF7),3,0))))) -> 0 | DH7: =IF(AND(DH8="",DI8=""),"No Jugado",IF(DH8>DI8,DH5,(IF(DH8=DI8,"Empate",DI5)))) -> No Jugado | DJ7: =IF(AND(DH$8="",DI$8=""),0,IF(AND(DH$8=DH7,DI$8=DI7),5,IF(AND(DH$8=DI$8,DH7=DI7),3,IF(AND(DH$8>DI$8,DH7>DI7),3,IF(AND(DH$8<DI$8,DH7<DI7),3,0))))) -> 0 | DK7: =IF(AND(DK8="",DL8=""),"No Jugado",IF(DK8>DL8,DK5,(IF(DK8=DL8,"Empate",DL5)))) -> No Jugado | DM7: =IF(AND(DK$8="",DL$8=""),0,IF(AND(DK$8=DK7,DL$8=DL7),5,IF(AND(DK$8=DL$8,DK7=DL7),3,IF(AND(DK$8>DL$8,DK7>DL7),3,IF(AND(DK$8<DL$8,DK7<DL7),3,0))))) -> 0 | DN7: =IF(AND(DN8="",DO8=""),"No Jugado",IF(DN8>DO8,DN5,(IF(DN8=DO8,"Empate",DO5)))) -> No Jugado | DP7: =IF(AND(DN$8="",DO$8=""),0,IF(AND(DN$8=DN7,DO$8=DO7),5,IF(AND(DN$8=DO$8,DN7=DO7),3,IF(AND(DN$8>DO$8,DN7>DO7),3,IF(AND(DN$8<DO$8,DN7<DO7),3,0))))) -> 0 | DQ7: =IF(AND(DQ8="",DR8=""),"No Jugado",IF(DQ8>DR8,DQ5,(IF(DQ8=DR8,"Empate",DR5)))) -> No Jugado | DS7: =IF(AND(DQ$8="",DR$8=""),0,IF(AND(DQ$8=DQ7,DR$8=DR7),5,IF(AND(DQ$8=DR$8,DQ7=DR7),3,IF(AND(DQ$8>DR$8,DQ7>DR7),3,IF(AND(DQ$8<DR$8,DQ7<DR7),3,0))))) -> 0 | DT7: =IF(AND(DT8="",DU8=""),"No Jugado",IF(DT8>DU8,DT5,(IF(DT8=DU8,"Empate",DU5)))) -> No Jugado | DV7: =IF(AND(DT$8="",DU$8=""),0,IF(AND(DT$8=DT7,DU$8=DU7),5,IF(AND(DT$8=DU$8,DT7=DU7),3,IF(AND(DT$8>DU$8,DT7>DU7),3,IF(AND(DT$8<DU$8,DT7<DU7),3,0))))) -> 0 | DW7: =IF(AND(DW8="",DX8=""),"No Jugado",IF(DW8>DX8,DW5,(IF(DW8=DX8,"Empate",DX5)))) -> No Jugado | DY7: =IF(AND(DW$8="",DX$8=""),0,IF(AND(DW$8=DW7,DX$8=DX7),5,IF(AND(DW$8=DX$8,DW7=DX7),3,IF(AND(DW$8>DX$8,DW7>DX7),3,IF(AND(DW$8<DX$8,DW7<DX7),3,0))))) -> 0 | DZ7: =IF(AND(DZ8="",EA8=""),"No Jugado",IF(DZ8>EA8,DZ5,(IF(DZ8=EA8,"Empate",EA5)))) -> No Jugado | EB7: =IF(AND(DZ$8="",EA$8=""),0,IF(AND(DZ$8=DZ7,EA$8=EA7),5,IF(AND(DZ$8=EA$8,DZ7=EA7),3,IF(AND(DZ$8>EA$8,DZ7>EA7),3,IF(AND(DZ$8<EA$8,DZ7<EA7),3,0))))) -> 0 | EC7: =IF(AND(EC8="",ED8=""),"No Jugado",IF(EC8>ED8,EC5,(IF(EC8=ED8,"Empate",ED5)))) -> No Jugado | EE7: =IF(AND(EC$8="",ED$8=""),0,IF(AND(EC$8=EC7,ED$8=ED7),5,IF(AND(EC$8=ED$8,EC7=ED7),3,IF(AND(EC$8>ED$8,EC7>ED7),3,IF(AND(EC$8<ED$8,EC7<ED7),3,0))))) -> 0 | EF7: =IF(AND(EF8="",EG8=""),"No Jugado",IF(EF8>EG8,EF5,(IF(EF8=EG8,"Empate",EG5)))) -> No Jugado | EH7: =IF(AND(EF$8="",EG$8=""),0,IF(AND(EF$8=EF7,EG$8=EG7),5,IF(AND(EF$8=EG$8,EF7=EG7),3,IF(AND(EF$8>EG$8,EF7>EG7),3,IF(AND(EF$8<EG$8,EF7<EG7),3,0))))) -> 0 | EI7: =IF(AND(EI8="",EJ8=""),"No Jugado",IF(EI8>EJ8,EI5,(IF(EI8=EJ8,"Empate",EJ5)))) -> No Jugado | EK7: =IF(AND(EI$8="",EJ$8=""),0,IF(AND(EI$8=EI7,EJ$8=EJ7),5,IF(AND(EI$8=EJ$8,EI7=EJ7),3,IF(AND(EI$8>EJ$8,EI7>EJ7),3,IF(AND(EI$8<EJ$8,EI7<EJ7),3,0))))) -> 0 | EL7: =IF(AND(EL8="",EM8=""),"No Jugado",IF(EL8>EM8,EL5,(IF(EL8=EM8,"Empate",EM5)))) -> No Jugado | EN7: =IF(AND(EL$8="",EM$8=""),0,IF(AND(EL$8=EL7,EM$8=EM7),5,IF(AND(EL$8=EM$8,EL7=EM7),3,IF(AND(EL$8>EM$8,EL7>EM7),3,IF(AND(EL$8<EM$8,EL7<EM7),3,0))))) -> 0 | EO7: =IF(AND(EO8="",EP8=""),"No Jugado",IF(EO8>EP8,EO5,(IF(EO8=EP8,"Empate",EP5)))) -> No Jugado | EQ7: =IF(AND(CS$8="",CT$8=""),0,IF(AND(CS$8=CS7,CT$8=CT7),5,IF(AND(CS$8=CT$8,CS7=CT7),3,IF(AND(CS$8>CT$8,CS7>CT7),3,IF(AND(CS$8<CT$8,CS7<CT7),3,0))))) -> 0 | ER7: =F7+I7+L7+O7+R7+U7+X7+AA7+AD7+AG7+AJ7+AM7+AP7+AS7+AV7+AY7 -> 21
C8: =ER8 -> 80 | D8: 0 | E8: 2 | F8: =IF(AND(D$8="",E$8=""),0,IF(AND(D$8=D8,E$8=E8),5,IF(AND(D$8=E$8,D8=E8),3,IF(AND(D$8>E$8,D8>E8),3,IF(AND(D$8<E$8,D8<E8),3,0))))) -> 5 | G8: 0 | H8: 2 | I8: =IF(AND(G$8="",H$8=""),0,IF(AND(G$8=G8,H$8=H8),5,IF(AND(G$8=H$8,G8=H8),3,IF(AND(G$8>H$8,G8>H8),3,IF(AND(G$8<H$8,G8<H8),3,0))))) -> 5 | J8: 6 | K8: 2 | L8: =IF(AND(J$8="",K$8=""),0,IF(AND(J$8=J8,K$8=K8),5,IF(AND(J$8=K$8,J8=K8),3,IF(AND(J$8>K$8,J8>K8),3,IF(AND(J$8<K$8,J8<K8),3,0))))) -> 5 | M8: 1 | N8: 1 | O8: =IF(AND(M$8="",N$8=""),0,IF(AND(M$8=M8,N$8=N8),5,IF(AND(M$8=N$8,M8=N8),3,IF(AND(M$8>N$8,M8>N8),3,IF(AND(M$8<N$8,M8<N8),3,0))))) -> 5 | P8: 1 | Q8: 2 | R8: =IF(AND(P$8="",Q$8=""),0,IF(AND(P$8=P8,Q$8=Q8),5,IF(AND(P$8=Q$8,P8=Q8),3,IF(AND(P$8>Q$8,P8>Q8),3,IF(AND(P$8<Q$8,P8<Q8),3,0))))) -> 5 | S8: 0 | T8: 0 | U8: =IF(AND(S$8="",T$8=""),0,IF(AND(S$8=S8,T$8=T8),5,IF(AND(S$8=T$8,S8=T8),3,IF(AND(S$8>T$8,S8>T8),3,IF(AND(S$8<T$8,S8<T8),3,0))))) -> 5 | V8: 0 | W8: 0 | X8: =IF(AND(V$8="",W$8=""),0,IF(AND(V$8=V8,W$8=W8),5,IF(AND(V$8=W$8,V8=W8),3,IF(AND(V$8>W$8,V8>W8),3,IF(AND(V$8<W$8,V8<W8),3,0))))) -> 5 | Y8: 4 | Z8: 1 | AA8: =IF(AND(Y$8="",Z$8=""),0,IF(AND(Y$8=Y8,Z$8=Z8),5,IF(AND(Y$8=Z$8,Y8=Z8),3,IF(AND(Y$8>Z$8,Y8>Z8),3,IF(AND(Y$8<Z$8,Y8<Z8),3,0))))) -> 5 | AB8: 1 | AC8: 2 | AD8: =IF(AND(AB$8="",AC$8=""),0,IF(AND(AB$8=AB8,AC$8=AC8),5,IF(AND(AB$8=AC$8,AB8=AC8),3,IF(AND(AB$8>AC$8,AB8>AC8),3,IF(AND(AB$8<AC$8,AB8<AC8),3,0))))) -> 5 | AE8: 5 | AF8: 0 | AG8: =IF(AND(AE$8="",AF$8=""),0,IF(AND(AE$8=AE8,AF$8=AF8),5,IF(AND(AE$8=AF$8,AE8=AF8),3,IF(AND(AE$8>AF$8,AE8>AF8),3,IF(AND(AE$8<AF$8,AE8<AF8),3,0))))) -> 5 | AH8: 0 | AI8: 0 | AJ8: =IF(AND(AH$8="",AI$8=""),0,IF(AND(AH$8=AH8,AI$8=AI8),5,IF(AND(AH$8=AI$8,AH8=AI8),3,IF(AND(AH$8>AI$8,AH8>AI8),3,IF(AND(AH$8<AI$8,AH8<AI8),3,0))))) -> 5 | AK8: 1 | AL8: 0 | AM8: =IF(AND(AK$8="",AL$8=""),0,IF(AND(AK$8=AK8,AL$8=AL8),5,IF(AND(AK$8=AL$8,AK8=AL8),3,IF(AND(AK$8>AL$8,AK8>AL8),3,IF(AND(AK$8<AL$8,AK8<AL8),3,0))))) -> 5 | AN8: 1 | AO8: 0 | AP8: =IF(AND(AN$8="",AO$8=""),0,IF(AND(AN$8=AN8,AO$8=AO8),5,IF(AND(AN$8=AO$8,AN8=AO8),3,IF(AND(AN$8>AO$8,AN8>AO8),3,IF(AND(AN$8<AO$8,AN8<AO8),3,0))))) -> 5 | AQ8: 2 | AR8: 0 | AS8: =IF(AND(AQ$8="",AR$8=""),0,IF(AND(AQ$8=AQ8,AR$8=AR8),5,IF(AND(AQ$8=AR$8,AQ8=AR8),3,IF(AND(AQ$8>AR$8,AQ8>AR8),3,IF(AND(AQ$8<AR$8,AQ8<AR8),3,0))))) -> 5 | AT8: 0 | AU8: 0 | AV8: =IF(AND(AT$8="",AU$8=""),0,IF(AND(AT$8=AT8,AU$8=AU8),5,IF(AND(AT$8=AU$8,AT8=AU8),3,IF(AND(AT$8>AU$8,AT8>AU8),3,IF(AND(AT$8<AU$8,AT8<AU8),3,0))))) -> 5 | AW8: 3 | AX8: 2 | AY8: =IF(AND(AW$8="",AX$8=""),0,IF(AND(AW$8=AW8,AX$8=AX8),5,IF(AND(AW$8=AX$8,AW8=AX8),3,IF(AND(AW$8>AX$8,AW8>AX8),3,IF(AND(AW$8<AX$8,AW8<AX8),3,0))))) -> 5 | AZ8: 0 | BA8: 1 | BB8: =IF(AND(AZ$8="",BA$8=""),0,IF(AND(AZ$8=AZ8,BA$8=BA8),5,IF(AND(AZ$8=BA$8,AZ8=BA8),3,IF(AND(AZ$8>BA$8,AZ8>BA8),3,IF(AND(AZ$8<BA$8,AZ8<BA8),3,0))))) -> 5 | BE8: =IF(AND(BC$8="",BD$8=""),0,IF(AND(BC$8=BC8,BD$8=BD8),5,IF(AND(BC$8=BD$8,BC8=BD8),3,IF(AND(BC$8>BD$8,BC8>BD8),3,IF(AND(BC$8<BD$8,BC8<BD8),3,0))))) -> 0 | BF8: 0 | BG8: 2 | BH8: =IF(AND(BF$8="",BG$8=""),0,IF(AND(BF$8=BF8,BG$8=BG8),5,IF(AND(BF$8=BG$8,BF8=BG8),3,IF(AND(BF$8>BG$8,BF8>BG8),3,IF(AND(BF$8<BG$8,BF8<BG8),3,0))))) -> 5 | BK8: =IF(AND(BI$8="",BJ$8=""),0,IF(AND(BI$8=BI8,BJ$8=BJ8),5,IF(AND(BI$8=BJ$8,BI8=BJ8),3,IF(AND(BI$8>BJ$8,BI8>BJ8),3,IF(AND(BI$8<BJ$8,BI8<BJ8),3,0))))) -> 0 | BN8: =IF(AND(BL$8="",BM$8=""),0,IF(AND(BL$8=BL8,BM$8=BM8),5,IF(AND(BL$8=BM$8,BL8=BM8),3,IF(AND(BL$8>BM$8,BL8>BM8),3,IF(AND(BL$8<BM$8,BL8<BM8),3,0))))) -> 0 | BQ8: =IF(AND(BO$8="",BP$8=""),0,IF(AND(BO$8=BO8,BP$8=BP8),5,IF(AND(BO$8=BP$8,BO8=BP8),3,IF(AND(BO$8>BP$8,BO8>BP8),3,IF(AND(BO$8<BP$8,BO8<BP8),3,0))))) -> 0 | BT8: =IF(AND(BR$8="",BS$8=""),0,IF(AND(BR$8=BR8,BS$8=BS8),5,IF(AND(BR$8=BS$8,BR8=BS8),3,IF(AND(BR$8>BS$8,BR8>BS8),3,IF(AND(BR$8<BS$8,BR8<BS8),3,0))))) -> 0 | BW8: =IF(AND(BU$8="",BV$8=""),0,IF(AND(BU$8=BU8,BV$8=BV8),5,IF(AND(BU$8=BV$8,BU8=BV8),3,IF(AND(BU$8>BV$8,BU8>BV8),3,IF(AND(BU$8<BV$8,BU8<BV8),3,0))))) -> 0 | BZ8: =IF(AND(BX$8="",BY$8=""),0,IF(AND(BX$8=BX8,BY$8=BY8),5,IF(AND(BX$8=BY$8,BX8=BY8),3,IF(AND(BX$8>BY$8,BX8>BY8),3,IF(AND(BX$8<BY$8,BX8<BY8),3,0))))) -> 0 | CC8: =IF(AND(CA$8="",CB$8=""),0,IF(AND(CA$8=CA8,CB$8=CB8),5,IF(AND(CA$8=CB$8,CA8=CB8),3,IF(AND(CA$8>CB$8,CA8>CB8),3,IF(AND(CA$8<CB$8,CA8<CB8),3,0))))) -> 0 | CF8: =IF(AND(CD$8="",CE$8=""),0,IF(AND(CD$8=CD8,CE$8=CE8),5,IF(AND(CD$8=CE$8,CD8=CE8),3,IF(AND(CD$8>CE$8,CD8>CE8),3,IF(AND(CD$8<CE$8,CD8<CE8),3,0))))) -> 0 | CI8: =IF(AND(CG$8="",CH$8=""),0,IF(AND(CG$8=CG8,CH$8=CH8),5,IF(AND(CG$8=CH$8,CG8=CH8),3,IF(AND(CG$8>CH$8,CG8>CH8),3,IF(AND(CG$8<CH$8,CG8<CH8),3,0))))) -> 0 | CL8: =IF(AND(CJ$8="",CK$8=""),0,IF(AND(CJ$8=CJ8,CK$8=CK8),5,IF(AND(CJ$8=CK$8,CJ8=CK8),3,IF(AND(CJ$8>CK$8,CJ8>CK8),3,IF(AND(CJ$8<CK$8,CJ8<CK8),3,0))))) -> 0 | CO8: =IF(AND(CM$8="",CN$8=""),0,IF(AND(CM$8=CM8,CN$8=CN8),5,IF(AND(CM$8=CN$8,CM8=CN8),3,IF(AND(CM$8>CN$8,CM8>CN8),3,IF(AND(CM$8<CN$8,CM8<CN8),3,0))))) -> 0 | CR8: =IF(AND(CP$8="",CQ$8=""),0,IF(AND(CP$8=CP8,CQ$8=CQ8),5,IF(AND(CP$8=CQ$8,CP8=CQ8),3,IF(AND(CP$8>CQ$8,CP8>CQ8),3,IF(AND(CP$8<CQ$8,CP8<CQ8),3,0))))) -> 0 | CU8: =IF(AND(CS$8="",CT$8=""),0,IF(AND(CS$8=CS8,CT$8=CT8),5,IF(AND(CS$8=CT$8,CS8=CT8),3,IF(AND(CS$8>CT$8,CS8>CT8),3,IF(AND(CS$8<CT$8,CS8<CT8),3,0))))) -> 0 | CX8: =IF(AND(CV$8="",CW$8=""),0,IF(AND(CV$8=CV8,CW$8=CW8),5,IF(AND(CV$8=CW$8,CV8=CW8),3,IF(AND(CV$8>CW$8,CV8>CW8),3,IF(AND(CV$8<CW$8,CV8<CW8),3,0))))) -> 0 | DA8: =IF(AND(CY$8="",CZ$8=""),0,IF(AND(CY$8=CY8,CZ$8=CZ8),5,IF(AND(CY$8=CZ$8,CY8=CZ8),3,IF(AND(CY$8>CZ$8,CY8>CZ8),3,IF(AND(CY$8<CZ$8,CY8<CZ8),3,0))))) -> 0 | DD8: =IF(AND(DB$8="",DC$8=""),0,IF(AND(DB$8=DB8,DC$8=DC8),5,IF(AND(DB$8=DC$8,DB8=DC8),3,IF(AND(DB$8>DC$8,DB8>DC8),3,IF(AND(DB$8<DC$8,DB8<DC8),3,0))))) -> 0 | DG8: =IF(AND(DE$8="",DF$8=""),0,IF(AND(DE$8=DE8,DF$8=DF8),5,IF(AND(DE$8=DF$8,DE8=DF8),3,IF(AND(DE$8>DF$8,DE8>DF8),3,IF(AND(DE$8<DF$8,DE8<DF8),3,0))))) -> 0 | DJ8: =IF(AND(DH$8="",DI$8=""),0,IF(AND(DH$8=DH8,DI$8=DI8),5,IF(AND(DH$8=DI$8,DH8=DI8),3,IF(AND(DH$8>DI$8,DH8>DI8),3,IF(AND(DH$8<DI$8,DH8<DI8),3,0))))) -> 0 | DM8: =IF(AND(DK$8="",DL$8=""),0,IF(AND(DK$8=DK8,DL$8=DL8),5,IF(AND(DK$8=DL$8,DK8=DL8),3,IF(AND(DK$8>DL$8,DK8>DL8),3,IF(AND(DK$8<DL$8,DK8<DL8),3,0))))) -> 0 | DP8: =IF(AND(DN$8="",DO$8=""),0,IF(AND(DN$8=DN8,DO$8=DO8),5,IF(AND(DN$8=DO$8,DN8=DO8),3,IF(AND(DN$8>DO$8,DN8>DO8),3,IF(AND(DN$8<DO$8,DN8<DO8),3,0))))) -> 0 | DS8: =IF(AND(DQ$8="",DR$8=""),0,IF(AND(DQ$8=DQ8,DR$8=DR8),5,IF(AND(DQ$8=DR$8,DQ8=DR8),3,IF(AND(DQ$8>DR$8,DQ8>DR8),3,IF(AND(DQ$8<DR$8,DQ8<DR8),3,0))))) -> 0 | DV8: =IF(AND(DT$8="",DU$8=""),0,IF(AND(DT$8=DT8,DU$8=DU8),5,IF(AND(DT$8=DU$8,DT8=DU8),3,IF(AND(DT$8>DU$8,DT8>DU8),3,IF(AND(DT$8<DU$8,DT8<DU8),3,0))))) -> 0 | DY8: =IF(AND(DW$8="",DX$8=""),0,IF(AND(DW$8=DW8,DX$8=DX8),5,IF(AND(DW$8=DX$8,DW8=DX8),3,IF(AND(DW$8>DX$8,DW8>DX8),3,IF(AND(DW$8<DX$8,DW8<DX8),3,0))))) -> 0 | EB8: =IF(AND(DZ$8="",EA$8=""),0,IF(AND(DZ$8=DZ8,EA$8=EA8),5,IF(AND(DZ$8=EA$8,DZ8=EA8),3,IF(AND(DZ$8>EA$8,DZ8>EA8),3,IF(AND(DZ$8<EA$8,DZ8<EA8),3,0))))) -> 0 | EE8: =IF(AND(EC$8="",ED$8=""),0,IF(AND(EC$8=EC8,ED$8=ED8),5,IF(AND(EC$8=ED$8,EC8=ED8),3,IF(AND(EC$8>ED$8,EC8>ED8),3,IF(AND(EC$8<ED$8,EC8<ED8),3,0))))) -> 0 | EH8: =IF(AND(EF$8="",EG$8=""),0,IF(AND(EF$8=EF8,EG$8=EG8),5,IF(AND(EF$8=EG$8,EF8=EG8),3,IF(AND(EF$8>EG$8,EF8>EG8),3,IF(AND(EF$8<EG$8,EF8<EG8),3,0))))) -> 0 | EK8: =IF(AND(EI$8="",EJ$8=""),0,IF(AND(EI$8=EI8,EJ$8=EJ8),5,IF(AND(EI$8=EJ$8,EI8=EJ8),3,IF(AND(EI$8>EJ$8,EI8>EJ8),3,IF(AND(EI$8<EJ$8,EI8<EJ8),3,0))))) -> 0 | EN8: =IF(AND(EL$8="",EM$8=""),0,IF(AND(EL$8=EL8,EM$8=EM8),5,IF(AND(EL$8=EM$8,EL8=EM8),3,IF(AND(EL$8>EM$8,EL8>EM8),3,IF(AND(EL$8<EM$8,EL8<EM8),3,0))))) -> 0 | EQ8: =IF(AND(CS$8="",CT$8=""),0,IF(AND(CS$8=CS8,CT$8=CT8),5,IF(AND(CS$8=CT$8,CS8=CT8),3,IF(AND(CS$8>CT$8,CS8>CT8),3,IF(AND(CS$8<CT$8,CS8<CT8),3,0))))) -> 0 | ER8: =F8+I8+L8+O8+R8+U8+X8+AA8+AD8+AG8+AJ8+AM8+AP8+AS8+AV8+AY8 -> 80
A9: 1 | B9: ARELYS SEGOVIA | C9: =ER9 -> 31 | D9: 1 | E9: 0 | F9: =IF(AND(D$8=D9,E$8=E9,D$8<>""),5,IF(AND(D$8>E$8,D9>E9,(D$8-E$8)=(D9-E9),D$8<>""),3,IF(AND(D$8<E$8,D9<E9,(E$8-D$8)=(E9-D9),D$8<>""),3,IF(AND((D$8-E$8)=0,(D9-E9)=0,D$8<>""),3,IF(AND(D$8<E$8,D9>E9),0,IF(AND(D$8>E$8,D9<E9),0,IF(AND(D$8>E$8,D9>E9,D$8<>""),1,IF(AND(D$8<E$8,D9<E9,D$8<>""),1,IF(AND(D$8="",E$8=""),0,0))))))))) -> 0 | G9: 1 | H9: 3 | I9: =IF(AND(G$8=G9,H$8=H9,G$8<>""),5,IF(AND(G$8>H$8,G9>H9,(G$8-H$8)=(G9-H9),G$8<>""),3,IF(AND(G$8<H$8,G9<H9,(H$8-G$8)=(H9-G9),G$8<>""),3,IF(AND((G$8-H$8)=0,(G9-H9)=0,G$8<>""),3,IF(AND(G$8<H$8,G9>H9),0,IF(AND(G$8>H$8,G9<H9),0,IF(AND(G$8>H$8,G9>H9,G$8<>""),1,IF(AND(G$8<H$8,G9<H9,G$8<>""),1,IF(AND(G$8="",H$8=""),0,0))))))))) -> 3 | J9: 2 | K9: 1 | L9: =IF(AND(J$8=J9,K$8=K9,J$8<>""),5,IF(AND(J$8>K$8,J9>K9,(J$8-K$8)=(J9-K9),J$8<>""),3,IF(AND(J$8<K$8,J9<K9,(K$8-J$8)=(K9-J9),J$8<>""),3,IF(AND((J$8-K$8)=0,(J9-K9)=0,J$8<>""),3,IF(AND(J$8<K$8,J9>K9),0,IF(AND(J$8>K$8,J9<K9),0,IF(AND(J$8>K$8,J9>K9,J$8<>""),1,IF(AND(J$8<K$8,J9<K9,J$8<>""),1,IF(AND(J$8="",K$8=""),0,0))))))))) -> 1 | M9: 0 | N9: 0 | O9: =IF(AND(M$8=M9,N$8=N9,M$8<>""),5,IF(AND(M$8>N$8,M9>N9,(M$8-N$8)=(M9-N9),M$8<>""),3,IF(AND(M$8<N$8,M9<N9,(N$8-M$8)=(N9-M9),M$8<>""),3,IF(AND((M$8-N$8)=0,(M9-N9)=0,M$8<>""),3,IF(AND(M$8<N$8,M9>N9),0,IF(AND(M$8>N$8,M9<N9),0,IF(AND(M$8>N$8,M9>N9,M$8<>""),1,IF(AND(M$8<N$8,M9<N9,M$8<>""),1,IF(AND(M$8="",N$8=""),0,0))))))))) -> 3 | P9: 3 | Q9: 0 | R9: =IF(AND(P$8=P9,Q$8=Q9,P$8<>""),5,IF(AND(P$8>Q$8,P9>Q9,(P$8-Q$8)=(P9-Q9),P$8<>""),3,IF(AND(P$8<Q$8,P9<Q9,(Q$8-P$8)=(Q9-P9),P$8<>""),3,IF(AND((P$8-Q$8)=0,(P9-Q9)=0,P$8<>""),3,IF(AND(P$8<Q$8,P9>Q9),0,IF(AND(P$8>Q$8,P9<Q9),0,IF(AND(P$8>Q$8,P9>Q9,P$8<>""),1,IF(AND(P$8<Q$8,P9<Q9,P$8<>""),1,IF(AND(P$8="",Q$8=""),0,0))))))))) -> 0 | S9: 1 | T9: 2 | U9: =IF(AND(S$8=S9,T$8=T9,S$8<>""),5,IF(AND(S$8>T$8,S9>T9,(S$8-T$8)=(S9-T9),S$8<>""),3,IF(AND(S$8<T$8,S9<T9,(T$8-S$8)=(T9-S9),S$8<>""),3,IF(AND((S$8-T$8)=0,(S9-T9)=0,S$8<>""),3,IF(AND(S$8<T$8,S9>T9),0,IF(AND(S$8>T$8,S9<T9),0,IF(AND(S$8>T$8,S9>T9,S$8<>""),1,IF(AND(S$8<T$8,S9<T9,S$8<>""),1,IF(AND(S$8="",T$8=""),0,0))))))))) -> 0 | V9: 2 | W9: 0 | X9: =IF(AND(V$8=V9,W$8=W9,V$8<>""),5,IF(AND(V$8>W$8,V9>W9,(V$8-W$8)=(V9-W9),V$8<>""),3,IF(AND(V$8<W$8,V9<W9,(W$8-V$8)=(W9-V9),V$8<>""),3,IF(AND((V$8-W$8)=0,(V9-W9)=0,V$8<>""),3,IF(AND(V$8<W$8,V9>W9),0,IF(AND(V$8>W$8,V9<W9),0,IF(AND(V$8>W$8,V9>W9,V$8<>""),1,IF(AND(V$8<W$8,V9<W9,V$8<>""),1,IF(AND(V$8="",W$8=""),0,0))))))))) -> 0 | Y9: 3 | Z9: 0 | AA9: =IF(AND(Y$8=Y9,Z$8=Z9,Y$8<>""),5,IF(AND(Y$8>Z$8,Y9>Z9,(Y$8-Z$8)=(Y9-Z9),Y$8<>""),3,IF(AND(Y$8<Z$8,Y9<Z9,(Z$8-Y$8)=(Z9-Y9),Y$8<>""),3,IF(AND((Y$8-Z$8)=0,(Y9-Z9)=0,Y$8<>""),3,IF(AND(Y$8<Z$8,Y9>Z9),0,IF(AND(Y$8>Z$8,Y9<Z9),0,IF(AND(Y$8>Z$8,Y9>Z9,Y$8<>""),1,IF(AND(Y$8<Z$8,Y9<Z9,Y$8<>""),1,IF(AND(Y$8="",Z$8=""),0,0))))))))) -> 3 | AB9: 3 | AC9: 1 | AD9: =IF(AND(AB$8=AB9,AC$8=AC9,AB$8<>""),5,IF(AND(AB$8>AC$8,AB9>AC9,(AB$8-AC$8)=(AB9-AC9),AB$8<>""),3,IF(AND(AB$8<AC$8,AB9<AC9,(AC$8-AB$8)=(AC9-AB9),AB$8<>""),3,IF(AND((AB$8-AC$8)=0,(AB9-AC9)=0,AB$8<>""),3,IF(AND(AB$8<AC$8,AB9>AC9),0,IF(AND(AB$8>AC$8,AB9<AC9),0,IF(AND(AB$8>AC$8,AB9>AC9,AB$8<>""),1,IF(AND(AB$8<AC$8,AB9<AC9,AB$8<>""),1,IF(AND(AB$8="",AC$8=""),0,0))))))))) -> 0 | AE9: 0 | AF9: 1 | AG9: =IF(AND(AE$8=AE9,AF$8=AF9,AE$8<>""),5,IF(AND(AE$8>AF$8,AE9>AF9,(AE$8-AF$8)=(AE9-AF9),AE$8<>""),3,IF(AND(AE$8<AF$8,AE9<AF9,(AE$8-AF$8)=(AE9-AF9),AE$8<>""),3,IF(AND((AE$8-AF$8)=0,(AE9-AF9)=0,AE$8<>""),3,IF(AND(AE$8<AF$8,AE9>AF9),0,IF(AND(AE$8>AF$8,AE9<AF9),0,IF(AND(AE$8>AF$8,AE9>AF9,AE$8<>""),1,IF(AND(AE$8<AF$8,AE9<AF9,AE$8<>""),1,IF(AND(AE$8="",AF$8=""),0,0))))))))) -> 0 | AH9: 0 | AI9: 0 | AJ9: =IF(AND(AH$8=AH9,AI$8=AI9,AH$8<>""),5,IF(AND(AH$8>AI$8,AH9>AI9,(AH$8-AI$8)=(AH9-AI9),AH$8<>""),3,IF(AND(AH$8<AI$8,AH9<AI9,(AH$8-AI$8)=(AH9-AI9),AH$8<>""),3,IF(AND((AH$8-AI$8)=0,(AH9-AI9)=0,AH$8<>""),3,IF(AND(AH$8<AI$8,AH9>AI9),0,IF(AND(AH$8>AI$8,AH9<AI9),0,IF(AND(AH$8>AI$8,AH9>AI9,AH$8<>""),1,IF(AND(AH$8<AI$8,AH9<AI9,AH$8<>""),1,IF(AND(AH$8="",AI$8=""),0,0))))))))) -> 5 | AK9: 1 | AL9: 0 | AM9: =IF(AND(AK$8=AK9,AL$8=AL9,AK$8<>""),5,IF(AND(AK$8>AL$8,AK9>AL9,(AK$8-AL$8)=(AK9-AL9),AK$8<>""),3,IF(AND(AK$8<AL$8,AK9<AL9,(AK$8-AL$8)=(AK9-AL9),AK$8<>""),3,IF(AND((AK$8-AL$8)=0,(AK9-AL9)=0,AK$8<>""),3,IF(AND(AK$8<AL$8,AK9>AL9),0,IF(AND(AK$8>AL$8,AK9<AL9),0,IF(AND(AK$8>AL$8,AK9>AL9,AK$8<>""),1,IF(AND(AK$8<AL$8,AK9<AL9,AK$8<>""),1,IF(AND(AK$8="",AL$8=""),0,0))))))))) -> 5 | AN9: 2 | AO9: 1 | AP9: =IF(AND(AN$8=AN9,AO$8=AO9,AN$8<>""),5,IF(AND(AN$8>AO$8,AN9>AO9,(AN$8-AO$8)=(AN9-AO9),AN$8<>""),3,IF(AND(AN$8<AO$8,AN9<AO9,(AN$8-AO$8)=(AN9-AO9),AN$8<>""),3,IF(AND((AN$8-AO$8)=0,(AN9-AO9)=0,AN$8<>""),3,IF(AND(AN$8<AO$8,AN9>AO9),0,IF(AND(AN$8>AO$8,AN9<AO9),0,IF(AND(AN$8>AO$8,AN9>AO9,AN$8<>""),1,IF(AND(AN$8<AO$8,AN9<AO9,AN$8<>""),1,IF(AND(AN$8="",AO$8=""),0,0))))))))) -> 3 | AQ9: 2 | AR9: 0 | AS9: =IF(AND(AQ$8=AQ9,AR$8=AR9,AQ$8<>""),5,IF(AND(AQ$8>AR8,AQ9>AR9,(AQ$8-AR$8)=(AQ9-AR9),AQ$8<>""),3,IF(AND(AQ$8<AR$8,AQ9<AR9,(AQ$8-AR$8)=(AQ9-AR9),AQ$8<>""),3,IF(AND((AQ$8-AR$8)=0,(AQ9-AR9)=0,AQ$8<>""),3,IF(AND(AQ$8<AR$8,AQ9>AR9),0,IF(AND(AQ$8>AR$8,AQ9<AR9),0,IF(AND(AQ$8>AR$8,AQ9>AR9,AQ$8<>""),1,IF(AND(AQ$8<AR$8,AQ9<AR9,AQ$8<>""),1,IF(AND(AQ$8="",AR$8=""),0,0))))))))) -> 5 | AT9: 0 | AU9: 1 | AV9: =IF(AND(AT$8=AT9,AU$8=AU9,AT$8<>""),5,IF(AND(AT$8>AU8,AT9>AU9,(AT$8-AU$8)=(AT9-AU9),AT$8<>""),3,IF(AND(AT$8<AU$8,AT9<AU9,(AT$8-AU$8)=(AT9-AU9),AT$8<>""),3,IF(AND((AT$8-AU$8)=0,(AT9-AU9)=0,AT$8<>""),3,IF(AND(AT$8<AU$8,AT9>AU9),0,IF(AND(AT$8>AU$8,AT9<AU9),0,IF(AND(AT$8>AU$8,AT9>AU9,AT$8<>""),1,IF(AND(AT$8<AU$8,AT9<AU9,AT$8<>""),1,IF(AND(AT$8="",AU$8=""),0,0))))))))) -> 0 | AW9: 3 | AX9: 1 | AY9: =IF(AND(AW$8=AW9,AX$8=AX9,AW$8<>""),5,IF(AND(AW$8>AX8,AW9>AX9,(AW$8-AX$8)=(AW9-AX9),AW$8<>""),3,IF(AND(AW$8<AX$8,AW9<AX9,(AW$8-AX$8)=(AW9-AX9),AW$8<>""),3,IF(AND((AW$8-AX$8)=0,(AW9-AX9)=0,AW$8<>""),3,IF(AND(AW$8<AX$8,AW9>AX9),0,IF(AND(AW$8>AX$8,AW9<AX9),0,IF(AND(AW$8>AX$8,AW9>AX9,AW$8<>""),1,IF(AND(AW$8<AX$8,AW9<AX9,AW$8<>""),1,IF(AND(AW$8="",AX$8=""),0,0))))))))) -> 1 | AZ9: 0 | BA9: 2 | BB9: =IF(AND(AZ$8=AZ9,BA$8=BA9,AZ$8<>""),5,IF(AND(AZ$8>BA8,AZ9>BA9,(AZ$8-BA$8)=(AZ9-BA9),AZ$8<>""),3,IF(AND(AZ$8<BA$8,AZ9<BA9,(AZ$8-BA$8)=(AZ9-BA9),AZ$8<>""),3,IF(AND((AZ$8-BA$8)=0,(AZ9-BA9)=0,AZ$8<>""),3,IF(AND(AZ$8<BA$8,AZ9>BA9),0,IF(AND(AZ$8>BA$8,AZ9<BA9),0,IF(AND(AZ$8>BA$8,AZ9>BA9,AZ$8<>""),1,IF(AND(AZ$8<BA$8,AZ9<BA9,AZ$8<>""),1,IF(AND(AZ$8="",BA$8=""),0,0))))))))) -> 1 | BC9: 2 | BD9: 0 | BE9: =IF(AND(BC$8=BC9,BD$8=BD9,BC$8<>""),5,IF(AND(BC$8>BD8,BC9>BD9,(BC$8-BD$8)=(BC9-BD9),BC$8<>""),3,IF(AND(BC$8<BD$8,BC9<BD9,(BC$8-BD$8)=(BC9-BD9),BC$8<>""),3,IF(AND((BC$8-BD$8)=0,(BC9-BD9)=0,BC$8<>""),3,IF(AND(BC$8<BD$8,BC9>BD9),0,IF(AND(BC$8>BD$8,BC9<BD9),0,IF(AND(BC$8>BD$8,BC9>BD9,BC$8<>""),1,IF(AND(BC$8<BD$8,BC9<BD9,BC$8<>""),1,IF(AND(BC$8="",BD$8=""),0,0))))))))) -> 0 | BF9: 0 | BG9: 1 | BH9: =IF(AND(BF$8=BF9,BG$8=BG9,BF$8<>""),5,IF(AND(BF$8>BG8,BF9>BG9,(BF$8-BG$8)=(BF9-BG9),BF$8<>""),3,IF(AND(BF$8<BG$8,BF9<BG9,(BF$8-BG$8)=(BF9-BG9),BF$8<>""),3,IF(AND((BF$8-BG$8)=0,(BF9-BG9)=0,BF$8<>""),3,IF(AND(BF$8<BG$8,BF9>BG9),0,IF(AND(BF$8>BG$8,BF9<BG9),0,IF(AND(BF$8>BG$8,BF9>BG9,BF$8<>""),1,IF(AND(BF$8<BG$8,BF9<BG9,BF$8<>""),1,IF(AND(BF$8="",BG$8=""),0,0))))))))) -> 1 | BI9: 2 | BJ9: 1 | BK9: =IF(AND(BI$8=BI9,BJ$8=BJ9,BI$8<>""),5,IF(AND(BI$8>BJ8,BI9>BJ9,(BI$8-BJ$8)=(BI9-BJ9),BI$8<>""),3,IF(AND(BI$8<BJ$8,BI9<BJ9,(BI$8-BJ$8)=(BI9-BJ9),BI$8<>""),3,IF(AND((BI$8-BJ$8)=0,(BI9-BJ9)=0,BI$8<>""),3,IF(AND(BI$8<BJ$8,BI9>BJ9),0,IF(AND(BI$8>BJ$8,BI9<BJ9),0,IF(AND(BI$8>BJ$8,BI9>BJ9,BI$8<>""),1,IF(AND(BI$8<BJ$8,BI9<BJ9,BI$8<>""),1,IF(AND(BI$8="",BJ$8=""),0,0))))))))) -> 0 | BL9: 1 | BM9: 0 | BN9: =IF(AND(BL$8=BL9,BM$8=BM9,BL$8<>""),5,IF(AND(BL$8>BM8,BL9>BM9,(BL$8-BM$8)=(BL9-BM9),BL$8<>""),3,IF(AND(BL$8<BM$8,BL9<BM9,(BL$8-BM$8)=(BL9-BM9),BL$8<>""),3,IF(AND((BM$8-BL$8)=0,(BL9-BM9)=0,BL$8<>""),3,IF(AND(BL$8<BM$8,BL9>BM9),0,IF(AND(BL$8>BM$8,BL9<BM9),0,IF(AND(BL$8>BM$8,BL9>BM9,BL$8<>""),1,IF(AND(BL$8<BM$8,BL9<BM9,BL$8<>""),1,IF(AND(BL$8="",BM$8=""),0,0))))))))) -> 0 | BO9: 1 | BP9: 1 | BQ9: =IF(AND(BO$8=BO9,BP$8=BP9,BO$8<>""),5,IF(AND(BO$8>BP8,BO9>BP9,(BO$8-BP$8)=(BO9-BP9),BO$8<>""),3,IF(AND(BO$8<BP$8,BO9<BP9,(BO$8-BP$8)=(BO9-BP9),BO$8<>""),3,IF(AND((BO$8-BP$8)=0,(BO9-BP9)=0,BO$8<>""),3,IF(AND(BO$8<BP$8,BO9>BP9),0,IF(AND(BO$8>BP$8,BO9<BP9),0,IF(AND(BO$8>BP$8,BO9>BP9,BO$8<>""),1,IF(AND(BO$8<BP$8,BO9<BP9,BO$8<>""),1,IF(AND(BO$8="",BP$8=""),0,0))))))))) -> 0 | BR9: 1 | BS9: 1 | BT9: =IF(AND(BR$8=BR9,BS$8=BS9,BR$8<>""),5,IF(AND(BR$8>BS8,BR9>BS9,(BR$8-BS$8)=(BR9-BS9),BR$8<>""),3,IF(AND(BR$8<BS$8,BR9<BS9,(BR$8-BS$8)=(BR9-BS9),BR$8<>""),3,IF(AND((BR$8-BS$8)=0,(BR9-BS9)=0,BR$8<>""),3,IF(AND(BR$8<BS$8,BR9>BS9),0,IF(AND(BR$8>BS$8,BR9<BS9),0,IF(AND(BR$8>BS$8,BR9>BS9,BR$8<>""),1,IF(AND(BR$8<BS$8,BR9<BS9,BR$8<>""),1,IF(AND(BR$8="",BS$8=""),0,0))))))))) -> 0 | BU9: 2 | BV9: 2 | BW9: =IF(AND(BU$8=BU9,BV$8=BV9,BU$8<>""),5,IF(AND(BU$8>BV8,BU9>BV9,(BU$8-BV$8)=(BU9-BV9),BU$8<>""),3,IF(AND(BU$8<BV$8,BU9<BV9,(BU$8-BV$8)=(BU9-BV9),BU$8<>""),3,IF(AND((BU$8-BV$8)=0,(BU9-BV9)=0,BU$8<>""),3,IF(AND(BU$8<BV$8,BU9>BV9),0,IF(AND(BU$8>BV$8,BU9<BV9),0,IF(AND(BU$8>BV$8,BU9>BV9,BU$8<>""),1,IF(AND(BU$8<BV$8,BU9<BV9,BU$8<>""),1,IF(AND(BU$8="",BV$8=""),0,0))))))))) -> 0 | BX9: 0 | BY9: 1 | BZ9: =IF(AND(BX$8=BX9,BY$8=BY9,BX$8<>""),5,IF(AND(BX$8>BY8,BX9>BY9,(BX$8-BY$8)=(BX9-BY9),BX$8<>""),3,IF(AND(BX$8<BY$8,BX9<BY9,(BX$8-BY$8)=(BX9-BY9),BX$8<>""),3,IF(AND((BX$8-BY$8)=0,(BX9-BY9)=0,BX$8<>""),3,IF(AND(BX$8<BY$8,BX9>BY9),0,IF(AND(BX$8>BY$8,BX9<BY9),0,IF(AND(BX$8>BY$8,BX9>BY9,BX$8<>""),1,IF(AND(BX$8<BY$8,BX9<BY9,BX$8<>""),1,IF(AND(BX$8="",BY$8=""),0,0))))))))) -> 0 | CA9: 0 | CB9: 2 | CC9: =IF(AND(CA$8=CA9,CB$8=CB9,CA$8<>""),5,IF(AND(CA$8>CB8,CA9>CB9,(CA$8-CB$8)=(CA9-CB9),CA$8<>""),3,IF(AND(CA$8<CB$8,CA9<CB9,(CA$8-CB$8)=(CA9-CB9),CA$8<>""),3,IF(AND((CA$8-CB$8)=0,(CA9-CB9)=0,CA$8<>""),3,IF(AND(CA$8<CB$8,CA9>CB9),0,IF(AND(CA$8>CB$8,CA9<CB9),0,IF(AND(CA$8>CB$8,CA9>CB9,CA$8<>""),1,IF(AND(CA$8<CB$8,CA9<CB9,CA$8<>""),1,IF(AND(CA$8="",CB$8=""),0,0))))))))) -> 0 | CD9: 2 | CE9: 1 | CF9: =IF(AND(CD$8=CD9,CE$8=CE9,CD$8<>""),5,IF(AND(CD$8>CE8,CD9>CE9,(CD$8-CE$8)=(CD9-CE9),CD$8<>""),3,IF(AND(CD$8<CE$8,CD9<CE9,(CD$8-CE$8)=(CD9-CE9),CD$8<>""),3,IF(AND((CD$8-CE$8)=0,(CD9-CE9)=0,CD$8<>""),3,IF(AND(CD$8<CE$8,CD9>CE9),0,IF(AND(CD$8>CE$8,CD9<CE9),0,IF(AND(CD$8>CE$8,CD9>CE9,CD$8<>""),1,IF(AND(CD$8<CE$8,CD9<CE9,CD$8<>""),1,IF(AND(CD$8="",CE$8=""),0,0))))))))) -> 0 | CG9: 2 | CH9: 0 | CI9: =IF(AND(CG$8=CG9,CH$8=CH9,CG$8<>""),5,IF(AND(CG$8>CH8,CG9>CH9,(CG$8-CH$8)=(CG9-CH9),CG$8<>""),3,IF(AND(CG$8<CH$8,CG9<CH9,(CG$8-CH$8)=(CG9-CH9),CG$8<>""),3,IF(AND((CG$8-CH$8)=0,(CG9-CH9)=0,CG$8<>""),3,IF(AND(CG$8<CH$8,CG9>CH9),0,IF(AND(CG$8>CH$8,CG9<CH9),0,IF(AND(CG$8>CH$8,CG9>CH9,CG$8<>""),1,IF(AND(CG$8<CH$8,CG9<CH9,CG$8<>""),1,IF(AND(CG$8="",CH$8=""),0,0))))))))) -> 0 | CJ9: 0 | CK9: 2 | CL9: =IF(AND(CJ$8=CJ9,CK$8=CK9,CJ$8<>""),5,IF(AND(CJ$8>CK8,CJ9>CK9,(CJ$8-CK$8)=(CJ9-CK9),CJ$8<>""),3,IF(AND(CJ$8<CK$8,CJ9<CK9,(CJ$8-CK$8)=(CJ9-CK9),CJ$8<>""),3,IF(AND((CJ$8-CK$8)=0,(CJ9-CK9)=0,CJ$8<>""),3,IF(AND(CJ$8<CK$8,CJ9>CK9),0,IF(AND(CJ$8>CK$8,CJ9<CK9),0,IF(AND(CJ$8>CK$8,CJ9>CK9,CJ$8<>""),1,IF(AND(CJ$8<CK$8,CJ9<CK9,CJ$8<>""),1,IF(AND(CJ$8="",CK$8=""),0,0))))))))) -> 0 | CM9: 1 | CN9: 0 | CO9: =IF(AND(CM$8=CM9,CN$8=CN9,CM$8<>""),5,IF(AND(CM$8>CN8,CM9>CN9,(CM$8-CN$8)=(CM9-CN9),CM$8<>""),3,IF(AND(CM$8<CN$8,CM9<CN9,(CM$8-CN$8)=(CM9-CN9),CM$8<>""),3,IF(AND((CM$8-CN$8)=0,(CM9-CN9)=0,CM$8<>""),3,IF(AND(CM$8<CN$8,CM9>CN9),0,IF(AND(CM$8>CN$8,CM9<CN9),0,IF(AND(CM$8>CN$8,CM9>CN9,CM$8<>""),1,IF(AND(CM$8<CN$8,CM9<CN9,CM$8<>""),1,IF(AND(CM$8="",CN$8=""),0,0))))))))) -> 0 | CP9: 0 | CQ9: 2 | CR9: =IF(AND(CP$8=CP9,CQ$8=CQ9,CP$8<>""),5,IF(AND(CP$8>CQ8,CP9>CQ9,(CP$8-CQ$8)=(CP9-CQ9),CP$8<>""),3,IF(AND(CP$8<CQ$8,CP9<CQ9,(CP$8-CQ$8)=(CP9-CQ9),CP$8<>""),3,IF(AND((CP$8-CQ$8)=0,(CP9-CQ9)=0,CP$8<>""),3,IF(AND(CP$8<CQ$8,CP9>CQ9),0,IF(AND(CP$8>CQ$8,CP9<CQ9),0,IF(AND(CP$8>CQ$8,CP9>CQ9,CP$8<>""),1,IF(AND(CP$8<CQ$8,CP9<CQ9,CP$8<>""),1,IF(AND(CP$8="",CQ$8=""),0,0))))))))) -> 0 | CS9: 2 | CT9: 1 | CU9: =IF(AND(CS$8=CS9,CT$8=CT9,CS$8<>""),5,IF(AND(CS$8>CT8,CS9>CT9,(CS$8-CT$8)=(CS9-CT9),CS$8<>""),3,IF(AND(CS$8<CT$8,CS9<CT9,(CS$8-CT$8)=(CS9-CT9),CS$8<>""),3,IF(AND((CS$8-CT$8)=0,(CS9-CT9)=0,CS$8<>""),3,IF(AND(CS$8<CT$8,CS9>CT9),0,IF(AND(CS$8>CT$8,CS9<CT9),0,IF(AND(CS$8>CT$8,CS9>CT9,CS$8<>""),1,IF(AND(CS$8<CT$8,CS9<CT9,CS$8<>""),1,IF(AND(CS$8="",CT$8=""),0,0))))))))) -> 0 | CV9: 1 | CW9: 2 | CX9: =IF(AND(CV$8=CV9,CW$8=CW9,CV$8<>""),5,IF(AND(CV$8>CW8,CV9>CW9,(CV$8-CW$8)=(CV9-CW9),CV$8<>""),3,IF(AND(CV$8<CW$8,CV9<CW9,(CV$8-CW$8)=(CV9-CW9),CV$8<>""),3,IF(AND((CV$8-CW$8)=0,(CV9-CW9)=0,CV$8<>""),3,IF(AND(CV$8<CW$8,CV9>CW9),0,IF(AND(CV$8>CW$8,CV9<CW9),0,IF(AND(CV$8>CW$8,CV9>CW9,CV$8<>""),1,IF(AND(CV$8<CW$8,CV9<CW9,CV$8<>""),1,IF(AND(CV$8="",CW$8=""),0,0))))))))) -> 0 | CY9: 2 | CZ9: 0 | DA9: =IF(AND(CY$8=CY9,CZ$8=CZ9,CY$8<>""),5,IF(AND(CY$8>CZ8,CY9>CZ9,(CY$8-CZ$8)=(CY9-CZ9),CY$8<>""),3,IF(AND(CY$8<CZ$8,CY9<CZ9,(CY$8-CZ$8)=(CY9-CZ9),CY$8<>""),3,IF(AND((CY$8-CZ$8)=0,(CY9-CZ9)=0,CY$8<>""),3,IF(AND(CY$8<CZ$8,CY9>CZ9),0,IF(AND(CY$8>CZ$8,CY9<CZ9),0,IF(AND(CY$8>CZ$8,CY9>CZ9,CY$8<>""),1,IF(AND(CY$8<CZ$8,CY9<CZ9,CY$8<>""),1,IF(AND(CY$8="",CZ$8=""),0,0))))))))) -> 0 | DB9: 0 | DC9: 3 | DD9: =IF(AND(DB$8=DB9,DC$8=DC9,DB$8<>""),5,IF(AND(DB$8>DC8,DB9>DC9,(DB$8-DC$8)=(DB9-DC9),DB$8<>""),3,IF(AND(DB$8<DC$8,DB9<DC9,(DB$8-DC$8)=(DB9-DC9),DB$8<>""),3,IF(AND((DB$8-DC$8)=0,(DB9-DC9)=0,DB$8<>""),3,IF(AND(DB$8<DC$8,DB9>DC9),0,IF(AND(DB$8>DC$8,DB9<DC9),0,IF(AND(DB$8>DC$8,DB9>DC9,DB$8<>""),1,IF(AND(DB$8<DC$8,DB9<DC9,DB$8<>""),1,IF(AND(DB$8="",DC$8=""),0,0))))))))) -> 0 | DE9: 1 | DF9: 2 | DG9: =IF(AND(DE$8=DE9,DF$8=DF9,DE$8<>""),5,IF(AND(DE$8>DF8,DE9>DF9,(DE$8-DF$8)=(DE9-DF9),DE$8<>""),3,IF(AND(DE$8<DF$8,DE9<DF9,(DE$8-DF$8)=(DE9-DF9),DE$8<>""),3,IF(AND((DE$8-DF$8)=0,(DE9-DF9)=0,DE$8<>""),3,IF(AND(DE$8<DF$8,DE9>DF9),0,IF(AND(DE$8>DF$8,DE9<DF9),0,IF(AND(DE$8>DF$8,DE9>DF9,DE$8<>""),1,IF(AND(DE$8<DF$8,DE9<DF9,DE$8<>""),1,IF(AND(DE$8="",DF$8=""),0,0))))))))) -> 0 | DH9: 1 | DI9: 2 | DJ9: =IF(AND(DH$8=DH9,DI$8=DI9,DH$8<>""),5,IF(AND(DH$8>DI8,DH9>DI9,(DH$8-DI$8)=(DH9-DI9),DH$8<>""),3,IF(AND(DH$8<DI$8,DH9<DI9,(DH$8-DI$8)=(DH9-DI9),DH$8<>""),3,IF(AND((DH$8-DI$8)=0,(DH9-DI9)=0,DH$8<>""),3,IF(AND(DH$8<DI$8,DH9>DI9),0,IF(AND(DH$8>DI$8,DH9<DI9),0,IF(AND(DH$8>DI$8,DH9>DI9,DH$8<>""),1,IF(AND(DH$8<DI$8,DH9<DI9,DH$8<>""),1,IF(AND(DH$8="",DI$8=""),0,0))))))))) -> 0 | DK9: 1 | DL9: 2 | DM9: =IF(AND(DK$8=DK9,DL$8=DL9,DK$8<>""),5,IF(AND(DK$8>DL8,DK9>DL9,(DK$8-DL$8)=(DK9-DL9),DK$8<>""),3,IF(AND(DK$8<DL$8,DK9<DL9,(DK$8-DL$8)=(DK9-DL9),DK$8<>""),3,IF(AND((DK$8-DL$8)=0,(DK9-DL9)=0,DK$8<>""),3,IF(AND(DK$8<DL$8,DK9>DL9),0,IF(AND(DK$8>DL$8,DK9<DL9),0,IF(AND(DK$8>DL$8,DK9>DL9,DK$8<>""),1,IF(AND(DK$8<DL$8,DK9<DL9,DK$8<>""),1,IF(AND(DK$8="",DL$8=""),0,0))))))))) -> 0 | DN9: 1 | DO9: 3 | DP9: =IF(AND(DN$8=DN9,DO$8=DO9,DN$8<>""),5,IF(AND(DN$8>DO8,DN9>DO9,(DN$8-DO$8)=(DN9-DO9),DN$8<>""),3,IF(AND(DN$8<DO$8,DN9<DO9,(DN$8-DO$8)=(DN9-DO9),DN$8<>""),3,IF(AND((DN$8-DO$8)=0,(DN9-DO9)=0,DN$8<>""),3,IF(AND(DN$8<DO$8,DN9>DO9),0,IF(AND(DN$8>DO$8,DN9<DO9),0,IF(AND(DN$8>DO$8,DN9>DO9,DN$8<>""),1,IF(AND(DN$8<DO$8,DN9<DO9,DN$8<>""),1,IF(AND(DN$8="",DO$8=""),0,0))))))))) -> 0 | DQ9: 0 | DR9: 2 | DS9: =IF(AND(DQ$8=DQ9,DR$8=DR9,DQ$8<>""),5,IF(AND(DQ$8>DR8,DQ9>DR9,(DQ$8-DR$8)=(DQ9-DR9),DQ$8<>""),3,IF(AND(DQ$8<DR$8,DQ9<DR9,(DQ$8-DR$8)=(DQ9-DR9),DQ$8<>""),3,IF(AND((DQ$8-DR$8)=0,(DQ9-DR9)=0,DQ$8<>""),3,IF(AND(DQ$8<DR$8,DQ9>DR9),0,IF(AND(DQ$8>DR$8,DQ9<DR9),0,IF(AND(DQ$8>DR$8,DQ9>DR9,DQ$8<>""),1,IF(AND(DQ$8<DR$8,DQ9<DR9,DQ$8<>""),1,IF(AND(DQ$8="",DR$8=""),0,0))))))))) -> 0 | DT9: 1 | DU9: 0 | DV9: =IF(AND(DT$8=DT9,DU$8=DU9,DT$8<>""),5,IF(AND(DT$8>DU8,DT9>DU9,(DT$8-DU$8)=(DT9-DU9),DT$8<>""),3,IF(AND(DT$8<DU$8,DT9<DU9,(DT$8-DU$8)=(DT9-DU9),DT$8<>""),3,IF(AND((DT$8-DU$8)=0,(DT9-DU9)=0,DT$8<>""),3,IF(AND(DT$8<DU$8,DT9>DU9),0,IF(AND(DT$8>DU$8,DT9<DU9),0,IF(AND(DT$8>DU$8,DT9>DU9,DT$8<>""),1,IF(AND(DT$8<DU$8,DT9<DU9,DT$8<>""),1,IF(AND(DT$8="",DU$8=""),0,0))))))))) -> 0 | DW9: 0 | DX9: 2 | DY9: =IF(AND(DW$8=DW9,DX$8=DX9,DW$8<>""),5,IF(AND(DW$8>DX8,DW9>DX9,(DW$8-DX$8)=(DW9-DX9),DW$8<>""),3,IF(AND(DW$8<DX$8,DW9<DX9,(DW$8-DX$8)=(DW9-DX9),DW$8<>""),3,IF(AND((DW$8-DX$8)=0,(DW9-DX9)=0,DW$8<>""),3,IF(AND(DW$8<DX$8,DW9>DX9),0,IF(AND(DW$8>DX$8,DW9<DX9),0,IF(AND(DW$8>DX$8,DW9>DX9,DW$8<>""),1,IF(AND(DW$8<DX$8,DW9<DX9,DW$8<>""),1,IF(AND(DW$8="",DX$8=""),0,0))))))))) -> 0 | DZ9: 1 | EA9: 1 | EB9: =IF(AND(DZ$8=DZ9,EA$8=EA9,DZ$8<>""),5,IF(AND(DZ$8>EA8,DZ9>EA9,(DZ$8-EA$8)=(DZ9-EA9),DZ$8<>""),3,IF(AND(DZ$8<EA$8,DZ9<EA9,(DZ$8-EA$8)=(DZ9-EA9),DZ$8<>""),3,IF(AND((DZ$8-EA$8)=0,(DZ9-EA9)=0,DZ$8<>""),3,IF(AND(DZ$8<EA$8,DZ9>EA9),0,IF(AND(DZ$8>EA$8,DZ9<EA9),0,IF(AND(DZ$8>EA$8,DZ9>EA9,DZ$8<>""),1,IF(AND(DZ$8<EA$8,DZ9<EA9,DZ$8<>""),1,IF(AND(DZ$8="",EA$8=""),0,0))))))))) -> 0 | EC9: 1 | ED9: 2 | EE9: =IF(AND(EC$8=EC9,ED$8=ED9,EC$8<>""),5,IF(AND(EC$8>ED8,EC9>ED9,(EC$8-ED$8)=(EC9-ED9),EC$8<>""),3,IF(AND(EC$8<ED$8,EC9<ED9,(EC$8-ED$8)=(EC9-ED9),EC$8<>""),3,IF(AND((EC$8-ED$8)=0,(EC9-ED9)=0,EC$8<>""),3,IF(AND(EC$8<ED$8,EC9>ED9),0,IF(AND(EC$8>ED$8,EC9<ED9),0,IF(AND(EC$8>ED$8,EC9>ED9,EC$8<>""),1,IF(AND(EC$8<ED$8,EC9<ED9,EC$8<>""),1,IF(AND(EC$8="",ED$8=""),0,0))))))))) -> 0 | EF9: 2 | EG9: 0 | EH9: =IF(AND(EF$8=EF9,EG$8=EG9,EF$8<>""),5,IF(AND(EF$8>EG8,EF9>EG9,(EF$8-EG$8)=(EF9-EG9),EF$8<>""),3,IF(AND(EF$8<EG$8,EF9<EG9,(EF$8-EG$8)=(EF9-EG9),EF$8<>""),3,IF(AND((EF$8-EG$8)=0,(EF9-EG9)=0,EF$8<>""),3,IF(AND(EF$8<EG$8,EF9>EG9),0,IF(AND(EF$8>EG$8,EF9<EG9),0,IF(AND(EF$8>EG$8,EF9>EG9,EF$8<>""),1,IF(AND(EF$8<EG$8,EF9<EG9,EF$8<>""),1,IF(AND(EF$8="",EG$8=""),0,0))))))))) -> 0 | EI9: 0 | EJ9: 2 | EK9: =IF(AND(EI$8=EI9,EJ$8=EJ9,EI$8<>""),5,IF(AND(EI$8>EJ8,EI9>EJ9,(EI$8-EJ$8)=(EI9-EJ9),EI$8<>""),3,IF(AND(EI$8<EJ$8,EI9<EJ9,(EI$8-EJ$8)=(EI9-EJ9),EI$8<>""),3,IF(AND((EI$8-EJ$8)=0,(EI9-EJ9)=0,EI$8<>""),3,IF(AND(EI$8<EJ$8,EI9>EJ9),0,IF(AND(EI$8>EJ$8,EI9<EJ9),0,IF(AND(EI$8>EJ$8,EI9>EJ9,EI$8<>""),1,IF(AND(EI$8<EJ$8,EI9<EJ9,EI$8<>""),1,IF(AND(EI$8="",EJ$8=""),0,0))))))))) -> 0 | EL9: 0 | EM9: 2 | EN9: =IF(AND(EL$8=EL9,EM$8=EM9,EL$8<>""),5,IF(AND(EL$8>EM8,EL9>EM9,(EL$8-EM$8)=(EL9-EM9),EL$8<>""),3,IF(AND(EL$8<EM$8,EL9<EM9,(EL$8-EM$8)=(EL9-EM9),EL$8<>""),3,IF(AND((EL$8-EM$8)=0,(EL9-EM9)=0,EL$8<>""),3,IF(AND(EL$8<EM$8,EL9>EM9),0,IF(AND(EL$8>EM$8,EL9<EM9),0,IF(AND(EL$8>EM$8,EL9>EM9,EL$8<>""),1,IF(AND(EL$8<EM$8,EL9<EM9,EL$8<>""),1,IF(AND(EL$8="",EM$8=""),0,0))))))))) -> 0 | EO9: 2 | EP9: 0 | EQ9: =IF(AND(EO$8=EO9,EP$8=EP9,EO$8<>""),5,IF(AND(EO$8>EP8,EO9>EP9,(EO$8-EP$8)=(EO9-EP9),EO$8<>""),3,IF(AND(EO$8<EP$8,EO9<EP9,(EO$8-EP$8)=(EO9-EP9),EO$8<>""),3,IF(AND((EO$8-EP$8)=0,(EO9-EP9)=0,EO$8<>""),3,IF(AND(EO$8<EP$8,EO9>EP9),0,IF(AND(EO$8>EP$8,EO9<EP9),0,IF(AND(EO$8>EP$8,EO9>EP9,EO$8<>""),1,IF(AND(EO$8<EP$8,EO9<EP9,EO$8<>""),1,IF(AND(EO$8="",EP$8=""),0,0))))))))) -> 0 | ER9: =F9+I9+L9+O9+R9+U9+X9+AA9+AD9+AG9+AJ9+AM9+AP9+AS9+AV9+AY9+BB9+BE9+BH9+BK9+BN9+BQ9+BT9+BW9+BZ9+CC9+CF9+CI9+CL9+CO9+CR9+CU9+CX9+DA9+DD9+DG9+DJ9+DM9+DP9+DS9+DV9+DY9+EB9+EE9+EH9+EK9+EN9+EQ9 -> 31
